Evaluation Reward at Epoch 1. Obs: -0.963, Exp: -0.969
Test Mazes results: [0]
Unexpected exception formatting exception. Falling back to standard exception
Traceback (most recent call last):
  File "C:\Users\Dickson Lim\AppData\Roaming\Python\Python39\site-packages\IPython\core\interactiveshell.py", line 3433, in run_code
    exec(code_obj, self.user_global_ns, self.user_ns)
  File "C:\Users\Dickson Lim\AppData\Local\Temp\ipykernel_22660\2993858147.py", line 132, in <module>
    human_collector.collect(n_episode=1, render=1/60)
  File "c:\Users\Dickson Lim\anaconda3\lib\site-packages\tianshou\data\collector.py", line 295, in collect
    obs_next, rew, terminated, truncated, info = self.env.step(
  File "c:\Users\Dickson Lim\anaconda3\lib\site-packages\tianshou\env\venvs.py", line 345, in step
    self.workers[j].send(action[i])
  File "c:\Users\Dickson Lim\anaconda3\lib\site-packages\tianshou\env\worker\dummy.py", line 38, in send
    self.result = self.env.step(action)  # type: ignore
  File "f:\Desktop\University\Exeter\ECMM451 Final Year Project\Final_Year_Project\env_utils\PettingZooEnv_new.py", line 68, in step
    self.env.step(action)
  File "c:\Users\Dickson Lim\anaconda3\lib\site-packages\supersuit\utils\base_aec_wrapper.py", line 46, in step
    super().step(action)
  File "c:\Users\Dickson Lim\anaconda3\lib\site-packages\pettingzoo\utils\wrappers\order_enforcing.py", line 81, in step
    super().step(action)
  File "c:\Users\Dickson Lim\anaconda3\lib\site-packages\pettingzoo\utils\wrappers\base.py", line 116, in step
    self.env.step(action)
  File "c:\Users\Dickson Lim\anaconda3\lib\site-packages\pettingzoo\utils\wrappers\order_enforcing.py", line 81, in step
    super().step(action)
  File "c:\Users\Dickson Lim\anaconda3\lib\site-packages\pettingzoo\utils\wrappers\base.py", line 116, in step
    self.env.step(action)
  File "c:\Users\Dickson Lim\anaconda3\lib\site-packages\pettingzoo\utils\wrappers\assert_out_of_bounds.py", line 29, in step
    super().step(action)
  File "c:\Users\Dickson Lim\anaconda3\lib\site-packages\pettingzoo\utils\wrappers\base.py", line 116, in step
    self.env.step(action)
  File "f:\Desktop\University\Exeter\ECMM451 Final Year Project\Final_Year_Project\maze_env\envs\maze.py", line 454, in step
    self.render()
  File "f:\Desktop\University\Exeter\ECMM451 Final Year Project\Final_Year_Project\maze_env\envs\maze.py", line 557, in render
    pass
  File "f:\Desktop\University\Exeter\ECMM451 Final Year Project\Final_Year_Project\maze_env\envs\maze.py", line 538, in _render_frame
KeyboardInterrupt
During handling of the above exception, another exception occurred:
Traceback (most recent call last):
  File "C:\Users\Dickson Lim\AppData\Roaming\Python\Python39\site-packages\IPython\core\interactiveshell.py", line 2052, in showtraceback
    stb = self.InteractiveTB.structured_traceback(
  File "C:\Users\Dickson Lim\AppData\Roaming\Python\Python39\site-packages\IPython\core\ultratb.py", line 1112, in structured_traceback
    return FormattedTB.structured_traceback(
  File "C:\Users\Dickson Lim\AppData\Roaming\Python\Python39\site-packages\IPython\core\ultratb.py", line 1006, in structured_traceback
    return VerboseTB.structured_traceback(
  File "C:\Users\Dickson Lim\AppData\Roaming\Python\Python39\site-packages\IPython\core\ultratb.py", line 859, in structured_traceback
    formatted_exception = self.format_exception_as_a_whole(etype, evalue, etb, number_of_lines_of_context,
  File "C:\Users\Dickson Lim\AppData\Roaming\Python\Python39\site-packages\IPython\core\ultratb.py", line 812, in format_exception_as_a_whole
    frames.append(self.format_record(r))
  File "C:\Users\Dickson Lim\AppData\Roaming\Python\Python39\site-packages\IPython\core\ultratb.py", line 730, in format_record
    result += ''.join(_format_traceback_lines(frame_info.lines, Colors, self.has_colors, lvals))
  File "C:\Users\Dickson Lim\AppData\Roaming\Python\Python39\site-packages\stack_data\utils.py", line 144, in cached_property_wrapper
    value = obj.__dict__[self.func.__name__] = self.func(obj)
  File "C:\Users\Dickson Lim\AppData\Roaming\Python\Python39\site-packages\stack_data\core.py", line 720, in lines
    pieces = self.included_pieces
  File "C:\Users\Dickson Lim\AppData\Roaming\Python\Python39\site-packages\stack_data\utils.py", line 144, in cached_property_wrapper
    value = obj.__dict__[self.func.__name__] = self.func(obj)
  File "C:\Users\Dickson Lim\AppData\Roaming\Python\Python39\site-packages\stack_data\core.py", line 667, in included_pieces
    pos = scope_pieces.index(self.executing_piece)
  File "C:\Users\Dickson Lim\AppData\Roaming\Python\Python39\site-packages\stack_data\utils.py", line 144, in cached_property_wrapper
    value = obj.__dict__[self.func.__name__] = self.func(obj)
  File "C:\Users\Dickson Lim\AppData\Roaming\Python\Python39\site-packages\stack_data\core.py", line 646, in executing_piece
    return only(
  File "C:\Users\Dickson Lim\AppData\Roaming\Python\Python39\site-packages\executing\executing.py", line 190, in only
    raise NotOneValueFound('Expected one value, found 0')
executing.executing.NotOneValueFound: Expected one value, found 0
wandb: WARNING Calling wandb.login() after wandb.init() has no effect.